Traceback (most recent call last):
  File "C:\Users\d.wu\PycharmProjects\netbox-vcenter-automation\venv\lib\site-packages\urllib3\connectionpool.py", line 467, in _make_request
    self._validate_conn(conn)
  File "C:\Users\d.wu\PycharmProjects\netbox-vcenter-automation\venv\lib\site-packages\urllib3\connectionpool.py", line 1099, in _validate_conn
    conn.connect()
  File "C:\Users\d.wu\PycharmProjects\netbox-vcenter-automation\venv\lib\site-packages\urllib3\connection.py", line 653, in connect
    sock_and_verified = _ssl_wrap_socket_and_match_hostname(
  File "C:\Users\d.wu\PycharmProjects\netbox-vcenter-automation\venv\lib\site-packages\urllib3\connection.py", line 806, in _ssl_wrap_socket_and_match_hostname
    ssl_sock = ssl_wrap_socket(
  File "C:\Users\d.wu\PycharmProjects\netbox-vcenter-automation\venv\lib\site-packages\urllib3\util\ssl_.py", line 465, in ssl_wrap_socket
    ssl_sock = _ssl_wrap_socket_impl(sock, context, tls_in_tls, server_hostname)
  File "C:\Users\d.wu\PycharmProjects\netbox-vcenter-automation\venv\lib\site-packages\urllib3\util\ssl_.py", line 509, in _ssl_wrap_socket_impl
    return ssl_context.wrap_socket(sock, server_hostname=server_hostname)
  File "C:\Program Files\Python39\lib\ssl.py", line 500, in wrap_socket
    return self.sslsocket_class._create(
  File "C:\Program Files\Python39\lib\ssl.py", line 1040, in _create
    self.do_handshake()
  File "C:\Program Files\Python39\lib\ssl.py", line 1309, in do_handshake
    self._sslobj.do_handshake()
ssl.SSLCertVerificationError: [SSL: CERTIFICATE_VERIFY_FAILED] certificate verify failed: unable to get local issuer certificate (_ssl.c:1129)

During handling of the above exception, another exception occurred:

Traceback (most recent call last):
  File "C:\Users\d.wu\PycharmProjects\netbox-vcenter-automation\venv\lib\site-packages\urllib3\connectionpool.py", line 793, in urlopen
    response = self._make_request(
  File "C:\Users\d.wu\PycharmProjects\netbox-vcenter-automation\venv\lib\site-packages\urllib3\connectionpool.py", line 491, in _make_request
    raise new_e
urllib3.exceptions.SSLError: [SSL: CERTIFICATE_VERIFY_FAILED] certificate verify failed: unable to get local issuer certificate (_ssl.c:1129)

The above exception was the direct cause of the following exception:

Traceback (most recent call last):
  File "C:\Users\d.wu\PycharmProjects\netbox-vcenter-automation\venv\lib\site-packages\requests\adapters.py", line 486, in send
    resp = conn.urlopen(
  File "C:\Users\d.wu\PycharmProjects\netbox-vcenter-automation\venv\lib\site-packages\urllib3\connectionpool.py", line 847, in urlopen
    retries = retries.increment(
  File "C:\Users\d.wu\PycharmProjects\netbox-vcenter-automation\venv\lib\site-packages\urllib3\util\retry.py", line 515, in increment
    raise MaxRetryError(_pool, url, reason) from reason  # type: ignore[arg-type]
urllib3.exceptions.MaxRetryError: HTTPSConnectionPool(host='142.107.6.177', port=443): Max retries exceeded with url: /api (Caused by SSLError(SSLCertVerificationError(1, '[SSL: CERTIFICATE_VERIFY_FAILED] certificate verify failed: unable to get local issuer certificate (_ssl.c:1129)')))

During handling of the above exception, another exception occurred:

Traceback (most recent call last):
  File "C:\Users\d.wu\PycharmProjects\netbox-vcenter-automation\tag-sync-test-01.py", line 193, in <module>
    main()
  File "C:\Users\d.wu\PycharmProjects\netbox-vcenter-automation\tag-sync-test-01.py", line 173, in main
    client = create_vsphere_client(server=ESXI_IP, username=USERNAME, password=PASSWORD)
  File "C:\Users\d.wu\PycharmProjects\netbox-vcenter-automation\venv\lib\site-packages\vmware\vapi\vsphere\client.py", line 173, in create_vsphere_client
    return VsphereClient(session=session, server=server, username=username,
  File "C:\Users\d.wu\PycharmProjects\netbox-vcenter-automation\venv\lib\site-packages\vmware\vapi\vsphere\client.py", line 116, in __init__
    session_id = session_svc.create()
  File "C:\Users\d.wu\PycharmProjects\netbox-vcenter-automation\venv\lib\site-packages\com\vmware\cis_client.py", line 202, in create
    return self._invoke('create', None)
  File "C:\Users\d.wu\PycharmProjects\netbox-vcenter-automation\venv\lib\site-packages\vmware\vapi\bindings\stub.py", line 345, in _invoke
    return self._api_interface.native_invoke(ctx, _method_name, kwargs)
  File "C:\Users\d.wu\PycharmProjects\netbox-vcenter-automation\venv\lib\site-packages\vmware\vapi\bindings\stub.py", line 266, in native_invoke
    method_result = self.invoke(ctx, method_id, data_val)
  File "C:\Users\d.wu\PycharmProjects\netbox-vcenter-automation\venv\lib\site-packages\vmware\vapi\bindings\stub.py", line 199, in invoke
    return self._api_provider.invoke(self._iface_id.get_name(),
  File "C:\Users\d.wu\PycharmProjects\netbox-vcenter-automation\venv\lib\site-packages\vmware\vapi\security\client\security_context_filter.py", line 101, in invoke
    method_result = ApiProviderFilter.invoke(
  File "C:\Users\d.wu\PycharmProjects\netbox-vcenter-automation\venv\lib\site-packages\vmware\vapi\provider\filter.py", line 75, in invoke
    method_result = self.next_provider.invoke(
  File "C:\Users\d.wu\PycharmProjects\netbox-vcenter-automation\venv\lib\site-packages\vmware\vapi\protocol\client\msg\json_connector.py", line 79, in invoke
    response = self._do_request(VAPI_INVOKE, ctx, params)
  File "C:\Users\d.wu\PycharmProjects\netbox-vcenter-automation\venv\lib\site-packages\vmware\vapi\protocol\client\msg\json_connector.py", line 151, in _do_request
    http_response = self.http_provider.do_request(
  File "C:\Users\d.wu\PycharmProjects\netbox-vcenter-automation\venv\lib\site-packages\vmware\vapi\protocol\client\rpc\requests_provider.py", line 95, in do_request
    output = self._session.request(
  File "C:\Users\d.wu\PycharmProjects\netbox-vcenter-automation\venv\lib\site-packages\requests\sessions.py", line 589, in request
    resp = self.send(prep, **send_kwargs)
  File "C:\Users\d.wu\PycharmProjects\netbox-vcenter-automation\venv\lib\site-packages\requests\sessions.py", line 703, in send
    r = adapter.send(request, **kwargs)
  File "C:\Users\d.wu\PycharmProjects\netbox-vcenter-automation\venv\lib\site-packages\requests\adapters.py", line 517, in send
    raise SSLError(e, request=request)
requests.exceptions.SSLError: HTTPSConnectionPool(host='142.107.6.177', port=443): Max retries exceeded with url: /api (Caused by SSLError(SSLCertVerificationError(1, '[SSL: CERTIFICATE_VERIFY_FAILED] certificate verify failed: unable to get local issuer certificate (_ssl.c:1129)')))

Process finished with exit code 1
